Workbook

Sheet sale may
A1: Name | B1: Keyboard | C1: Mouse | D1: Monitor | E1: Mouse Pad | F1: Pendrive (8 GB) | G1: Headphone
A2: Jyoti | B2: 22 | C2: 22 | D2: 19 | E2: 26 | F2: 13 | G2: 10
A3: Sakshi | B3: 26 | C3: 17 | D3: 21 | E3: 13 | F3: 16 | G3: 27
A4: Amit | B4: 18 | C4: 18 | D4: 27 | E4: 18 | F4: 16 | G4: 28
A5: Rohini | B5: 10 | C5: 27 | D5: 16 | E5: 14 | F5: 29 | G5: 9
A6: Rohan | B6: 17 | C6: 26 | D6: 15 | E6: 12 | F6: 9 | G6: 28
A7: Radhika | B7: 8 | C7: 8 | D7: 21 | E7: 19 | F7: 28 | G7: 26
A8: Vansh | B8: 28 | C8: 29 | D8: 30 | E8: 9 | F8: 24 | G8: 16
A9: Dimpal | B9: 11 | C9: 30 | D9: 21 | E9: 28 | F9: 29 | G9: 29
A10: Sagar | B10: 16 | C10: 18 | D10: 21 | E10: 13 | F10: 27 | G10: 8
A11: Sumit | B11: 17 | C11: 30 | D11: 15 | E11: 30 | F11: 24 | G11: 8
A12: Purvi | B12: 20 | C12: 22 | D12: 18 | E12: 22 | F12: 11 | G12: 12
A13: Aniket | B13: 27 | C13: 9 | D13: 12 | E13: 10 | F13: 22 | G13: 22
... A19: Total | B19: 319 | C19: 346 | D19: 330 | E19: 319 | F19: 320 | G19: 303

Sheet sale june
A1: Name | B1: Keyboard | C1: Mouse | D1: Monitor | E1: Mouse Pad | F1: Pendrive (8 GB) | G1: Headphone
A2: Jyoti | B2: 15 | C2: 25 | D2: 12 | E2: 20 | F2: 18 | G2: 14
A3: Sakshi | B3: 19 | C3: 20 | D3: 28 | E3: 15 | F3: 22 | G3: 18
A4: Amit | B4: 25 | C4: 14 | D4: 19 | E4: 22 | F4: 11 | G4: 20
A5: Rohini | B5: 14 | C5: 18 | D5: 22 | E5: 17 | F5: 25 | G5: 12
A6: Rohan | B6: 21 | C6: 19 | D6: 10 | E6: 25 | F6: 14 | G6: 22
A7: Radhika | B7: 12 | C7: 15 | D7: 25 | E7: 11 | F7: 20 | G7: 19
A8: Vansh | B8: 30 | C8: 22 | D8: 17 | E8: 18 | F8: 16 | G8: 25
A9: Dimpal | B9: 18 | C9: 27 | D9: 14 | E9: 21 | F9: 28 | G9: 17
A10: Sagar | B10: 22 | C10: 11 | D10: 18 | E10: 29 | F10: 19 | G10: 15
A11: Sumit | B11: 26 | C11: 24 | D11: 20 | E11: 12 | F11: 15 | G11: 21
A12: Purvi | B12: 11 | C12: 16 | D12: 29 | E12: 19 | F12: 23 | G12: 28
A13: Aniket | B13: 17 | C13: 28 | D13: 15 | E13: 24 | F13: 10 | G13: 16
... A19: Total | B19: 331 | C19: 320 | D19: 324 | E19: 342 | F19: 331 | G19: 312

Sheet sale july
A1: Name | B1: Keyboard | C1: Mouse | D1: Monitor | E1: Mouse Pad | F1: Pendrive (8 GB) | G1: Headphone
A2: Jyoti | B2: 45 | C2: 10 | D2: 24 | E2: 14 | F2: 21 | G2: 22
A3: Sakshi | B3: 12 | C3: 29 | D3: 15 | E3: 27 | F3: 11 | G3: 10
A4: Amit | B4: 20 | C4: 21 | D4: 11 | E4: 16 | F4: 29 | G4: 15
A5: Rohini | B5: 27 | C5: 12 | D5: 28 | E5: 23 | F5: 12 | G5: 26
A6: Rohan | B6: 10 | C6: 17 | D6: 22 | E6: 19 | F6: 27 | G6: 14
A7: Radhika | B7: 24 | C7: 26 | D7: 13 | E7: 28 | F7: 15 | G7: 21
A8: Vansh | B8: 16 | C8: 11 | D8: 26 | E8: 10 | F8: 18 | G8: 29
A9: Dimpal | B9: 22 | C9: 15 | D9: 19 | E9: 25 | F9: 13 | G9: 12
A10: Sagar | B10: 29 | C10: 28 | D10: 10 | E10: 12 | F10: 24 | G10: 20
A11: Sumit | B11: 11 | C11: 13 | D11: 25 | E11: 21 | F11: 20 | G11: 25
A12: Purvi | B12: 25 | C12: 20 | D12: 16 | E12: 15 | F12: 17 | G12: 18
A13: Aniket | B13: 19 | C13: 22 | D13: 21 | E13: 29 | F13: 26 | G13: 13
... A19: Total | B19: 355 | C19: 332 | D19: 330 | E19: 353 | F19: 333 | G19: 323

Sheet Sheet5
I6: Keyboard | J6: Mouse | K6: Monitor | L6: Mouse Pad | M6: Pendrive (8 GB) | N6: Headphone
I7: ='sale july'!$B$2 -> 45 | J7: ='sale july'!$C$2 -> 10 | K7: ='sale july'!$D$2 -> 24 | L7: ='sale july'!$E$2 -> 14 | M7: ='sale july'!$F$2 -> 21 | N7: ='sale july'!$G$2 -> 22
I8: ='sale june'!$B$2 -> 15 | J8: ='sale june'!$C$2 -> 25 | K8: ='sale june'!$D$2 -> 12 | L8: ='sale june'!$E$2 -> 20 | M8: ='sale june'!$F$2 -> 18 | N8: ='sale june'!$G$2 -> 14
I9: ='sale may'!$B$2 -> 22 | J9: ='sale may'!$C$2 -> 22 | K9: ='sale may'!$D$2 -> 19 | L9: ='sale may'!$E$2 -> 26 | M9: ='sale may'!$F$2 -> 13 | N9: ='sale may'!$G$2 -> 10
H10: Jyoti | I10: =SUM(I7:I9) -> 82 | J10: =SUM(J7:J9) -> 57 | K10: =SUM(K7:K9) -> 55 | L10: =SUM(L7:L9) -> 60 | M10: =SUM(M7:M9) -> 52 | N10: =SUM(N7:N9) -> 46 | O10: =SUM(I10:N10) -> 352
I11: ='sale july'!$B$3 -> 12 | J11: ='sale july'!$C$3 -> 29 | K11: ='sale july'!$D$3 -> 15 | L11: ='sale july'!$E$3 -> 27 | M11: ='sale july'!$F$3 -> 11 | N11: ='sale july'!$G$3 -> 10
I12: ='sale june'!$B$3 -> 19 | J12: ='sale june'!$C$3 -> 20 | K12: ='sale june'!$D$3 -> 28 | L12: ='sale june'!$E$3 -> 15 | M12: ='sale june'!$F$3 -> 22 | N12: ='sale june'!$G$3 -> 18
I13: ='sale may'!$B$3 -> 26 | J13: ='sale may'!$C$3 -> 17 | K13: ='sale may'!$D$3 -> 21 | L13: ='sale may'!$E$3 -> 13 | M13: ='sale may'!$F$3 -> 16 | N13: ='sale may'!$G$3 -> 27
H14: Sakshi | I14: =SUM(I11:I13) -> 57 | J14: =SUM(J11:J13) -> 66 | K14: =SUM(K11:K13) -> 64 | L14: =SUM(L11:L13) -> 55 | M14: =SUM(M11:M13) -> 49 | N14: =SUM(N11:N13) -> 55
I15: ='sale july'!$B$4 -> 20 | J15: ='sale july'!$C$4 -> 21 | K15: ='sale july'!$D$4 -> 11 | L15: ='sale july'!$E$4 -> 16 | M15: ='sale july'!$F$4 -> 29 | N15: ='sale july'!$G$4 -> 15
I16: ='sale june'!$B$4 -> 25 | J16: ='sale june'!$C$4 -> 14 | K16: ='sale june'!$D$4 -> 19 | L16: ='sale june'!$E$4 -> 22 | M16: ='sale june'!$F$4 -> 11 | N16: ='sale june'!$G$4 -> 20
I17: ='sale may'!$B$4 -> 18 | J17: ='sale may'!$C$4 -> 18 | K17: ='sale may'!$D$4 -> 27 | L17: ='sale may'!$E$4 -> 18 | M17: ='sale may'!$F$4 -> 16 | N17: ='sale may'!$G$4 -> 28
H18: Amit | I18: =SUM(I15:I17) -> 63 | J18: =SUM(J15:J17) -> 53 | K18: =SUM(K15:K17) -> 57 | L18: =SUM(L15:L17) -> 56 | M18: =SUM(M15:M17) -> 56 | N18: =SUM(N15:N17) -> 63
I19: ='sale july'!$B$5 -> 27 | J19: ='sale july'!$C$5 -> 12 | K19: ='sale july'!$D$5 -> 28 | L19: ='sale july'!$E$5 -> 23 | M19: ='sale july'!$F$5 -> 12 | N19: ='sale july'!$G$5 -> 26
I20: ='sale june'!$B$5 -> 14 | J20: ='sale june'!$C$5 -> 18 | K20: ='sale june'!$D$5 -> 22 | L20: ='sale june'!$E$5 -> 17 | M20: ='sale june'!$F$5 -> 25 | N20: ='sale june'!$G$5 -> 12
I21: ='sale may'!$B$5 -> 10 | J21: ='sale may'!$C$5 -> 27 | K21: ='sale may'!$D$5 -> 16 | L21: ='sale may'!$E$5 -> 14 | M21: ='sale may'!$F$5 -> 29 | N21: ='sale may'!$G$5 -> 9
H22: Rohini | I22: =SUM(I19:I21) -> 51 | J22: =SUM(J19:J21) -> 57 | K22: =SUM(K19:K21) -> 66 | L22: =SUM(L19:L21) -> 54 | M22: =SUM(M19:M21) -> 66 | N22: =SUM(N19:N21) -> 47
I23: ='sale july'!$B$6 -> 10 | J23: ='sale july'!$C$6 -> 17 | K23: ='sale july'!$D$6 -> 22 | L23: ='sale july'!$E$6 -> 19 | M23: ='sale july'!$F$6 -> 27 | N23: ='sale july'!$G$6 -> 14
I24: ='sale june'!$B$6 -> 21 | J24: ='sale june'!$C$6 -> 19 | K24: ='sale june'!$D$6 -> 10 | L24: ='sale june'!$E$6 -> 25 | M24: ='sale june'!$F$6 -> 14 | N24: ='sale june'!$G$6 -> 22
I25: ='sale may'!$B$6 -> 17 | J25: ='sale may'!$C$6 -> 26 | K25: ='sale may'!$D$6 -> 15 | L25: ='sale may'!$E$6 -> 12 | M25: ='sale may'!$F$6 -> 9 | N25: ='sale may'!$G$6 -> 28
H26: Rohan | I26: =SUM(I23:I25) -> 48 | J26: =SUM(J23:J25) -> 62 | K26: =SUM(K23:K25) -> 47 | L26: =SUM(L23:L25) -> 56 | M26: =SUM(M23:M25) -> 50 | N26: =SUM(N23:N25) -> 64
I27: ='sale july'!$B$7 -> 24 | J27: ='sale july'!$C$7 -> 26 | K27: ='sale july'!$D$7 -> 13 | L27: ='sale july'!$E$7 -> 28 | M27: ='sale july'!$F$7 -> 15 | N27: ='sale july'!$G$7 -> 21
I28: ='sale june'!$B$7 -> 12 | J28: ='sale june'!$C$7 -> 15 | K28: ='sale june'!$D$7 -> 25 | L28: ='sale june'!$E$7 -> 11 | M28: ='sale june'!$F$7 -> 20 | N28: ='sale june'!$G$7 -> 19
I29: ='sale may'!$B$7 -> 8 | J29: ='sale may'!$C$7 -> 8 | K29: ='sale may'!$D$7 -> 21 | L29: ='sale may'!$E$7 -> 19 | M29: ='sale may'!$F$7 -> 28 | N29: ='sale may'!$G$7 -> 26
H30: Radhika | I30: =SUM(I27:I29) -> 44 | J30: =SUM(J27:J29) -> 49 | K30: =SUM(K27:K29) -> 59 | L30: =SUM(L27:L29) -> 58 | M30: =SUM(M27:M29) -> 63 | N30: =SUM(N27:N29) -> 66
I31: ='sale july'!$B$8 -> 16 | J31: ='sale july'!$C$8 -> 11 | K31: ='sale july'!$D$8 -> 26 | L31: ='sale july'!$E$8 -> 10 | M31: ='sale july'!$F$8 -> 18 | N31: ='sale july'!$G$8 -> 29
I32: ='sale june'!$B$8 -> 30 | J32: ='sale june'!$C$8 -> 22 | K32: ='sale june'!$D$8 -> 17 | L32: ='sale june'!$E$8 -> 18 | M32: ='sale june'!$F$8 -> 16 | N32: ='sale june'!$G$8 -> 25
I33: ='sale may'!$B$8 -> 28 | J33: ='sale may'!$C$8 -> 29 | K33: ='sale may'!$D$8 -> 30 | L33: ='sale may'!$E$8 -> 9 | M33: ='sale may'!$F$8 -> 24 | N33: ='sale may'!$G$8 -> 16
H34: Vansh | I34: =SUM(I31:I33) -> 74 | J34: =SUM(J31:J33) -> 62 | K34: =SUM(K31:K33) -> 73 | L34: =SUM(L31:L33) -> 37 | M34: =SUM(M31:M33) -> 58 | N34: =SUM(N31:N33) -> 70
I35: ='sale july'!$B$9 -> 22 | J35: ='sale july'!$C$9 -> 15 | K35: ='sale july'!$D$9 -> 19 | L35: ='sale july'!$E$9 -> 25 | M35: ='sale july'!$F$9 -> 13 | N35: ='sale july'!$G$9 -> 12
I36: ='sale june'!$B$9 -> 18 | J36: ='sale june'!$C$9 -> 27 | K36: ='sale june'!$D$9 -> 14 | L36: ='sale june'!$E$9 -> 21 | M36: ='sale june'!$F$9 -> 28 | N36: ='sale june'!$G$9 -> 17
I37: ='sale may'!$B$9 -> 11 | J37: ='sale may'!$C$9 -> 30 | K37: ='sale may'!$D$9 -> 21 | L37: ='sale may'!$E$9 -> 28 | M37: ='sale may'!$F$9 -> 29 | N37: ='sale may'!$G$9 -> 29
H38: Dimpal | I38: =SUM(I35:I37) -> 51 | J38: =SUM(J35:J37) -> 72 | K38: =SUM(K35:K37) -> 54 | L38: =SUM(L35:L37) -> 74 | M38: =SUM(M35:M37) -> 70 | N38: =SUM(N35:N37) -> 58
I39: ='sale july'!$B$10 -> 29 | J39: ='sale july'!$C$10 -> 28 | K39: ='sale july'!$D$10 -> 10 | L39: ='sale july'!$E$10 -> 12 | M39: ='sale july'!$F$10 -> 24 | N39: ='sale july'!$G$10 -> 20
I40: ='sale june'!$B$10 -> 22 | J40: ='sale june'!$C$10 -> 11 | K40: ='sale june'!$D$10 -> 18 | L40: ='sale june'!$E$10 -> 29 | M40: ='sale june'!$F$10 -> 19 | N40: ='sale june'!$G$10 -> 15
I41: ='sale may'!$B$10 -> 16 | J41: ='sale may'!$C$10 -> 18 | K41: ='sale may'!$D$10 -> 21 | L41: ='sale may'!$E$10 -> 13 | M41: ='sale may'!$F$10 -> 27 | N41: ='sale may'!$G$10 -> 8
H42: Sagar | I42: =SUM(I39:I41) -> 67 | J42: =SUM(J39:J41) -> 57 | K42: =SUM(K39:K41) -> 49 | L42: =SUM(L39:L41) -> 54 | M42: =SUM(M39:M41) -> 70 | N42: =SUM(N39:N41) -> 43
I43: ='sale july'!$B$11 -> 11 | J43: ='sale july'!$C$11 -> 13 | K43: ='sale july'!$D$11 -> 25 | L43: ='sale july'!$E$11 -> 21 | M43: ='sale july'!$F$11 -> 20 | N43: ='sale july'!$G$11 -> 25
I44: ='sale june'!$B$11 -> 26 | J44: ='sale june'!$C$11 -> 24 | K44: ='sale june'!$D$11 -> 20 | L44: ='sale june'!$E$11 -> 12 | M44: ='sale june'!$F$11 -> 15 | N44: ='sale june'!$G$11 -> 21
I45: ='sale may'!$B$11 -> 17 | J45: ='sale may'!$C$11 -> 30 | K45: ='sale may'!$D$11 -> 15 | L45: ='sale may'!$E$11 -> 30 | M45: ='sale may'!$F$11 -> 24 | N45: ='sale may'!$G$11 -> 8
...

Sheet Sheet6
A1: Day | B1: Name | C1: City | D1: State | E1: Keyboard | F1: Mouse | G1: Monitor | H1: Mouse Pad | I1: Pendrive (8 GB) | J1: Headphone | K1: Total Sales
A2: Day 1 | B2: Jyoti | C2: Delhi | D2: Guna | E2: 22 | F2: 22 | G2: 19 | H2: 26 | I2: 13 | J2: 10 | K2: 112
A3: Day 1 | B3: Sakshi | C3: Mumbai | D3: Maharashtra | E3: 26 | F3: 17 | G3: 21 | H3: 13 | I3: 16 | J3: 27 | K3: 120
A4: Day 1 | B4: Amit | C4: Bangalore | D4: Karnataka | E4: 18 | F4: 18 | G4: 27 | H4: 18 | I4: 16 | J4: 28 | K4: 125
A5: Day 1 | B5: Rohini | C5: Kolkata | D5: West Bengal | E5: 10 | F5: 27 | G5: 16 | H5: 14 | I5: 29 | J5: 9 | K5: 105
A6: Day 1 | B6: Rohan | C6: Chennai | D6: Tamil Nadu | E6: 17 | F6: 26 | G6: 15 | H6: 12 | I6: 9 | J6: 28 | K6: 107
A7: Day 1 | B7: Radhika | C7: Hyderabad | D7: Telangana | E7: 8 | F7: 8 | G7: 21 | H7: 19 | I7: 28 | J7: 26 | K7: 110
A8: Day 1 | B8: Vansh | C8: Pune | D8: Maharashtra | E8: 28 | F8: 29 | G8: 30 | H8: 9 | I8: 24 | J8: 16 | K8: 136
A9: Day 1 | B9: Dimpal | C9: Ahmedabad | D9: Gujarat | E9: 11 | F9: 30 | G9: 21 | H9: 28 | I9: 29 | J9: 29 | K9: 148
A10: Day 1 | B10: Sagar | C10: Jaipur | D10: Rajasthan | E10: 16 | F10: 18 | G10: 21 | H10: 13 | I10: 27 | J10: 8 | K10: 103
A11: Day 1 | B11: Sumit | C11: Lucknow | D11: Uttar Pradesh | E11: 17 | F11: 30 | G11: 15 | H11: 30 | I11: 24 | J11: 8 | K11: 124
A12: Day 1 | B12: Purvi | C12: Chandigarh | D12: Punjab | E12: 20 | F12: 22 | G12: 18 | H12: 22 | I12: 11 | J12: 12 | K12: 105
A13: Day 1 | B13: Aniket | C13: Patna | D13: Bihar | E13: 27 | F13: 9 | G13: 12 | H13: 10 | I13: 22 | J13: 22 | K13: 102
... A52: Day 3 | B52: Varun | C52: Nagpur | D52: Maharashtra | E52: 18 | F52: 25 | G52: 14 | H52: 22 | I52: 19 | J52: 11 | K52: 109
